Workbook
Name _1_0_0_F: #REF!
Name _2_0_0_F: #REF!
Name _3q45_: {"'용역비'!$A$4:$C$8"}
Name _Dist_Bin: #REF!
Name _Dist_Values: #REF!
Name _Fill: #REF!
Name _Key1: #REF!
Name _Key2: #REF!
Name _Order1: 255
Name _Order2: 255
Name _q45: {"'용역비'!$A$4:$C$8"}
Name _Sort: #REF!
Name AccessDatabase: "D:\공무jaje\98년품의-수불\98146.mdb"
Name cgmh: {"'용역비'!$A$4:$C$8"}
Name DFEE: #REF!
Name dhj: {"'용역비'!$A$4:$C$8"}
Name DKSG: #REF!
Name DKSGMLWJD: #REF!
Name Dp: #REF!
Name dsgfggg: #REF!
Name DW: {"'용역비'!$A$4:$C$8"}
Name ED: #REF!
Name EFG: {"'용역비'!$A$4:$C$8"}
Name EGE: {"'용역비'!$A$4:$C$8"}
Name ertyertye: {"'용역비'!$A$4:$C$8"}
Name ETYETY: {"'용역비'!$A$4:$C$8"}
Name etyj: {"'용역비'!$A$4:$C$8"}
Name etyjj: {"'용역비'!$A$4:$C$8"}
Name ETYJTYJ: {"'용역비'!$A$4:$C$8"}
Name f: #REF!
Name FK: {"'용역비'!$A$4:$C$8"}
Name GEMCO: #REF!
Name GMLWD: #REF!
Name HHH: #REF!
Name HHHH: #REF!
Name HSR: {"'용역비'!$A$4:$C$8"}
Name HTML_CodePage: 949
Name HTML_Control: {"'용역비'!$A$4:$C$8"}
Name HTML_Description: ""
Name HTML_Email: ""
Name HTML_Header: "용역비"
Name HTML_LastUpdate: "99-07-01"
Name HTML_LineAfter: FALSE
Name HTML_LineBefore: FALSE
Name HTML_Name: "전산실"
Name HTML_OBDlg2: TRUE
Name HTML_OBDlg4: TRUE
Name HTML_OS: 0
Name HTML_PathFile: "C:\My Documents\MyHTML.htm"
Name HTML_Title: "전체금액"
Name IIII: {"'용역비'!$A$4:$C$8"}
Name IIIII: {"'용역비'!$A$4:$C$8"}
Name IOI: {"'용역비'!$A$4:$C$8"}
Name li: {"'용역비'!$A$4:$C$8"}
Name OIL: {"'용역비'!$A$4:$C$8"}
Name OP: #REF!
Name OPP: #REF!
Name QA: #REF!
Name QWS: #REF!
Name qyk: {"'용역비'!$A$4:$C$8"}

Sheet 표지

Sheet 3. 전경사진
A2: ='2. 실사개요'!B3 -> ㅇㅇㅇ아파트 플러그링크 충전인프라 구축사업
A4: 전경사진 첨부

Sheet 2. 실사개요
A1: 실 사 보 고 서
A3: 사 업 명 : | B3: ㅇㅇㅇ아파트 플러그링크 충전인프라 구축사업 | I3: 현장실사자 :
A4: 실사일시 | C4: : | D4: 2025-00-00 | J4: 연락처/팩스 | K4: : | L4: T 02-0000-0000 / F 02-0000-0000 / H 실사동행자 홍길동 000-0000-0000
A5: 현장명 | C5: : | D5: ㅇㅇㅇ아파트 | J5: 설치예정수량 | K5: : | L5: 신규 ( )기, 교체 ( )기
A6: 주 소 | C6: : | J6: 기설치대수 | K6: : | L6: ex) 한전 완속 00기 / 한전 급속 00기
A8: 설치위치 | F8: 설치정보 | I8: 인입점(1차) 분전반 정보 | M8: 배관 | O8: 배선 | Q8: 기자재
A9: 분전반구분 | B9: 상세위치 | F9: 대수 | G9: 종류 | H9: 신규/교체 | I9: 분전반 이름 | J9: 메인차단기 용량 | L9: 인입점차단기 용량 | M9: SIZE | N9: 길이 | O9: SIZE | P9: 길이 | Q9: 통신 | R9: 스탠드 | S9: 캐노피 | T9: 볼라드
A10: 1안 - 실사자 제안
A11: 1 | B11: (지상/지하) 층 동 기둥 | J11: P A | L11: P A | Q11: 1 | R11: 2 | S11: 3 | T11: 4
A12: 2 | B12: (지상/지하) 층 동 기둥 | J12: P A | L12: P A
A13: 3 | B13: (지상/지하) 층 동 기둥 | J13: P A | L13: P A
A14: 4 | B14: (지상/지하) 층 동 기둥 | J14: P A | L14: P A
A15: 5 | B15: (지상/지하) 층 동 기둥 | J15: P A | L15: P A
A16: 6 | B16: (지상/지하) 층 동 기둥 | J16: P A | L16: P A
A17: 2안 - 고객 요청
A18: 1 | B18: (지상/지하) 층 동 기둥 | J18: P A | L18: P A
A19: 2 | B19: (지상/지하) 층 동 기둥 | J19: P A | L19: P A
A20: 3 | B20: (지상/지하) 층 동 기둥 | J20: P A | L20: P A
A21: 4 | B21: (지상/지하) 층 동 기둥 | J21: P A | L21: P A
A22: 5 | B22: (지상/지하) 층 동 기둥 | J22: P A | L22: P A
A23: 6 | B23: (지상/지하) 층 동 기둥 | J23: P A | L23: P A
A24: ※ 현장 특이사항

Sheet 3. 도면
A1: 설 치 계 획 도 면(평면도)
A4: (주차장 평면도)
A51: 현 장 명 | F51: ='2. 실사개요'!D5 -> ㅇㅇㅇ아파트 | M51: 설 치 위 치 | R51: 지하주차장 00층
A53: 공 사 명 | F53: ='2. 실사개요'!B3 -> ㅇㅇㅇ아파트 플러그링크 충전인프라 구축사업 | M53: 설 치 수 량 | R53: 충전기 00대 / 통신함 00대

Sheet 4. 사진대지
A1: 사진대지
A3: 상세위치 | D3: 동 층 기둥 | I3: 인입분전반 Panel 명 | Q3: 설치수량 | T3: 신규( )기, 교체( )기
A4: 인입차단기용량 | D4: 1차측 메인 ( )A / 사용 차단기 ( )A | I4: 포설길이 | L4: 배관( )m, 배선( )m | Q4: 통신모뎀 | T4: ( )기
A5: 특이사항
A6: 사진 첨부(공란 시 내용 삭제) | M6: 사진 첨부(공란 시 내용 삭제)
A29: 사진설명 | D29: 도면 확대도 | M29: 사진설명 | P29: 1차측 분전반 내부
A31: 사진 첨부(공란 시 내용 삭제) | M31: 사진 첨부(공란 시 내용 삭제)
A54: 사진설명 | D54: 설치예정 위치 | M54: 사진설명 | P54: 전력간선 인입라인 - 1
A56: 사진 첨부(공란 시 내용 삭제) | M56: 사진 첨부(공란 시 내용 삭제)
A79: 사진설명 | D79: 전력간선 인입라인 - 2 | M79: 사진설명 | P79: 1차측 분전반 외부
A81: 사진 첨부(공란 시 내용 삭제) | M81: 사진 첨부(공란 시 내용 삭제)
A104: 사진설명 | D104: 1차측 분전반 내부 | M104: 사진설명 | P104: CCTV(지하설치)
A106: 사진 첨부(공란 시 내용 삭제) | M106: 사진 첨부(공란 시 내용 삭제)
A129: 사진설명 | D129: 전력간선 인입라인 - 3 | M129: 사진설명 | P129: 1차측 분전반 외부
A131: 사진 첨부(공란 시 내용 삭제) | M131: 사진 첨부(공란 시 내용 삭제)
A154: 사진설명 | D154: 1차측 분전반 내부 | M154: 사진설명 | P154: CCTV(지하설치)

Sheet 5. 공사내역서(입력)
B2: 항목 | D2: 수량 | E2: 단위 | F2: 사양 | G2: 작성법 | H2: 단가(변동 시 수정 가능)
B3: 기자재 | C3: 충전기 (신규) | E3: ea | F3: 7kW급 완속충전기 | G3: 신규 충전기 수 기입 | H3: 550000 | I3: 원
C4: 충전기 (교체) | E4: ea | F4: 7kW급 완속충전기 | G4: 교체 충전기 수 기입 | H4: 550000 | I4: 원
A5: 추가비용 | C5: 캐노피 | E5: ea | F5: W400 x D300 x H500 | G5: 캐노피 수 기입 | H5: 70000 | I5: 원
C6: 스탠드 | E6: ea | F6: W125xD75XH1550 | G6: 스탠드 수 기입 | H6: 65000 | I6: 원
C7: 볼라드 | E7: ea | F7: Ⅰ형 H700 | G7: 볼라드 수 기입 | H7: 40000 | I7: 원
B8: 공사 | C8: 도로커팅 | E8: m | G8: 도로커팅이 필요한 경우에 거리 기입, 오른쪽 단가는 조정 가능 | H8: 0 | I8: 원/m
C9: 땅파기 | E9: m | G9: 땅파기 필요한 경우에 거리 기입, 오른쪽 단가는 조정 가능 | H9: 0 | I9: 원/m
C10: 추가 배선공사 | E10: m | F10: 0.6/1kv F-CV 4C×6㎟ | G10: 기본 전기공사 초과분 입력 | H10: 5150 | I10: 원/m
E11: m | F11: 0.6/1kv F-CV 4C×10㎟ | G11: 기본 전기공사 초과분 입력 | H11: 8400 | I11: 원/m
E12: m | F12: 0.6/1kv F-CV 4C×16㎟ | G12: 기본 전기공사 초과분 입력 | H12: 12650 | I12: 원/m
E13: m | F13: 0.6/1kv F-CV 4C×25㎟ | G13: 기본 전기공사 초과분 입력 | H13: 19800 | I13: 원/m
E14: m | F14: 0.6/1kv F-CV 4C×35㎟ | G14: 기본 전기공사 초과분 입력 | H14: 27100 | I14: 원/m
E15: m | F15: 0.6/1kv F-CV 4C×50㎟ | G15: 기본 전기공사 초과분 입력 | H15: 36500 | I15: 원/m
E16: m | F16: 0.6/1kv F-CV 1C×70㎟ (4ea) | G16: 기본 전기공사 초과분 입력 (전체길이를 4가닥으로 나눈 값) | H16: 51000 | I16: 원/m
E17: m | F17: 0.6/1kv F-CV 1C×95㎟ (4ea) | G17: 기본 전기공사 초과분 입력 (전체길이를 4가닥으로 나눈 값) | H17: 70800 | I17: 원/m
E18: m | F18: 0.6/1kv F-CV 1C×120㎟ (4ea) | G18: 기본 전기공사 초과분 입력 (전체길이를 4가닥으로 나눈 값) | H18: 88200 | I18: 원/m
E19: m | F19: 0.6/1kv F-CV 1C×150㎟ (4ea) | G19: 기본 전기공사 초과분 입력 (전체길이를 4가닥으로 나눈 값) | H19: 109700 | I19: 원/m
C20: 추가 강제전선관 배관 공사 | E20: m | F20: 아연도 16mm | G20: 기본 전기공사 초과분 입력 | H20: 3250 | I20: 원/m
E21: m | F21: 아연도 22mm | G21: 기본 전기공사 초과분 입력 | H21: 4300 | I21: 원/m
E22: m | F22: 아연도 28mm | G22: 기본 전기공사 초과분 입력 | H22: 5700 | I22: 원/m
E23: m | F23: 아연도 36mm | G23: 기본 전기공사 초과분 입력 | H23: 7350 | I23: 원/m
E24: m | F24: 아연도 42mm | G24: 기본 전기공사 초과분 입력 | H24: 8400 | I24: 원/m
E25: m | F25: 아연도 54mm | G25: 기본 전기공사 초과분 입력 | H25: 11900 | I25: 원/m
E26: m | F26: 아연도 70mm | G26: 기본 전기공사 초과분 입력 | H26: 15100 | I26: 원/m
E27: m | F27: 아연도 82mm | G27: 기본 전기공사 초과분 입력 | H27: 17400 | I27: 원/m
E28: m | F28: 아연도 104mm | G28: 기본 전기공사 초과분 입력 | H28: 28200 | I28: 원/m
C29: 기타비용 | F29: 인건비 | H29: 250000
A39: 시공사부담 | B39: 시공사 부담금 | G39: 시공사 부담가능금액 입력
A40: 추가비용 | B40: 한전인입 | C40: 예상용량 | E40: kW | G40: 7kW x 충전기 수량
C41: 계통견적포함 | D41: No | G41: 한전에 계통연계를 하는 경우 "Yes", 모자분리일 경우 "No"
C42: 계통타입 | D42: 공중공급 | G42: 한전 연계를 공중으로 하면 "공중", 지중으로 하면 "지중"
C43: 초과거리(신설) | D43: 0 | E43: m | G43: 공중(200m), 지중(50m) 초과하는 거리를 연계하는 경우 초과거리 기입(신설), 어려우면 0으로
C44: 초과거리(첨가) | D44: 0 | E44: m | G44: 공중(200m), 지중(50m) 초과하는 거리를 연계하는 경우 초과거리 기입(첨가), 어려우면 0으로
C45: 예상계통연계비 | D45: =IF(D41="No",0,IF(D42="공중공급",306000+(D40-5)*121000+53000*D43+7000*D44,588000+(D40-5)*141000+75000*D43)) -> 0 | G45: 자동계산 됨
B46: 전기안전점검 | C46: 거점수 | E46: 개소 | G46: 전기안전점검을 진행하는 총 거점수(분전반 기준) / 사용전점검 및 사용검사 제외 | H46: 44000
C47: 충전기 총수량 | E47: ea | G47: 전기안전점검을 진행하는 총 충전기수량 / 사용전점검 및 사용검사 제외 | H47: 7400
C48: 견적포함여부 | D48: No | G48: 전기안전점검을 진행하는 경우 "YES", 그렇지 않은 경우 "NO"
C49: 전기안전점검 수수료 | D49: =IF(D48="No",0,IF(D48="YES",D46*H46+D47*H47)) -> 0 | G49: 자동계산 됨

Sheet 공사내역서(출력)
G1: pluglink,Inc.
G2: 서울시 서초구 강남대로 311, 11층 1107호
G3: TEL : 1533-0702 FAX : 02-6499-0704
A6: ='2. 실사개요'!B3 -> ㅇㅇㅇ아파트 플러그링크 충전인프라 구축사업
A7: 공사내역서
A10: 1. 상세내역
A11: 구분 | B11: 품목명 | E11: 상 세 | G11: 수 량 | I11: 단 가 | K11: 가 격 | M11: 공사 내역 요약(파트너사 및 PL확인용)
A12: ※ 주요 기자재 | M12: 차감비용 합계(영업사) | N12: =SUM(K14:K16)+SUM(K20:K50)+K51-K55+K52 -> 0
A13: 충전기 | E13: ='5. 공사내역서(입력)'!F3 -> 7kW급 완속충전기 | G13: =SUM('5. 공사내역서(입력)'!D3:D4) -> 0 | H13: ='5. 공사내역서(입력)'!E3 -> ea | I13: ='5. 공사내역서(입력)'!H3 -> 550000 | K13: =G13*I13 -> 0 | M13: 대당 차감비용(영업사) | N13: =N12/G13 -> #DIV/0!
A14: 캐노피(헬멧) | E14: ='5. 공사내역서(입력)'!F5 -> W400 x D300 x H500 | G14: ='5. 공사내역서(입력)'!D5 -> 0 | H14: 개 | I14: ='5. 공사내역서(입력)'!H5 -> 70000 | K14: =G14*I14 -> 0 | M14: 지급공사비 합계(시공사) | N14: =SUM(K14:K50)-K55+K52 -> 0
A15: 스탠드(폴대) | E15: ='5. 공사내역서(입력)'!F6 -> W125xD75XH1550 | G15: ='5. 공사내역서(입력)'!D6 -> 0 | H15: 개 | I15: ='5. 공사내역서(입력)'!H6 -> 65000 | K15: =G15*I15 -> 0 | M15: 대당 지급공사비 합계(시공사) | N15: =N14/G13 -> #DIV/0!
A16: 볼라드(방호구조물) | E16: ='5. 공사내역서(입력)'!F7 -> Ⅰ형 H700 | G16: ='5. 공사내역서(입력)'!D7 -> 0 | H16: 개 | I16: ='5. 공사내역서(입력)'!H7 -> 40000 | K16: =G16*I16 -> 0 | M16: 플러그링크 사업비 합계(PL) | N16: =SUM(K13:K50)+K51-K55+K52 -> 0
A17: ※ 공사비 | M17: 플러그링크 대당 사업비(PL) | N17: =N16/G13 -> #DIV/0!
A18: 전기공사(신규) | E18: 완속충전기 기본 배관 및 배선 공사 | G18: ='5. 공사내역서(입력)'!D3 -> 0 | H18: 식 | I18: 900000 | K18: =G18*I18 -> 0
A19: 전기공사(교체) | E19: 완속충전기 교체 공사 | G19: ='5. 공사내역서(입력)'!D4 -> 0 | H19: 식 | I19: 250000 | K19: =G19*I19 -> 0
A20: ='5. 공사내역서(입력)'!C8 -> 도로커팅 | E20: ='5. 공사내역서(입력)'!F8 -> 0 | G20: ='5. 공사내역서(입력)'!D8 -> 0 | H20: m | I20: ='5. 공사내역서(입력)'!H8 -> 0 | K20: =G20*I20 -> 0
A21: ='5. 공사내역서(입력)'!C9 -> 땅파기 | E21: ='5. 공사내역서(입력)'!F9 -> 0 | G21: ='5. 공사내역서(입력)'!D9 -> 0 | H21: m | I21: ='5. 공사내역서(입력)'!H9 -> 0 | K21: =G21*I21 -> 0
A22: ='5. 공사내역서(입력)'!C10 -> 추가 배선공사 | E22: =IF(G22>0,'5. 공사내역서(입력)'!F10," ") | G22: ='5. 공사내역서(입력)'!D10 -> 0 | H22: =IF(G22>0,"m","") | I22: ='5. 공사내역서(입력)'!H10 -> 5150 | K22: =G22*I22 -> 0
E23: =IF(G23>0,'5. 공사내역서(입력)'!F11," ") | G23: ='5. 공사내역서(입력)'!D11 -> 0 | H23: =IF(G23>0,"m","") | I23: ='5. 공사내역서(입력)'!H11 -> 8400 | K23: =G23*I23 -> 0
E24: =IF(G24>0,'5. 공사내역서(입력)'!F12," ") | G24: ='5. 공사내역서(입력)'!D12 -> 0 | H24: =IF(G24>0,"m","") | I24: ='5. 공사내역서(입력)'!H12 -> 12650 | K24: =G24*I24 -> 0
E25: =IF(G25>0,'5. 공사내역서(입력)'!F13," ") | G25: ='5. 공사내역서(입력)'!D13 -> 0 | H25: =IF(G25>0,"m","") | I25: ='5. 공사내역서(입력)'!H13 -> 19800 | K25: =G25*I25 -> 0
E26: =IF(G26>0,'5. 공사내역서(입력)'!F14," ") | G26: ='5. 공사내역서(입력)'!D14 -> 0 | H26: =IF(G26>0,"m","") | I26: ='5. 공사내역서(입력)'!H14 -> 27100 | K26: =G26*I26 -> 0
E27: =IF(G27>0,'5. 공사내역서(입력)'!F15," ") | G27: ='5. 공사내역서(입력)'!D15 -> 0 | H27: =IF(G27>0,"m","") | I27: ='5. 공사내역서(입력)'!H15 -> 36500 | K27: =G27*I27 -> 0
E28: =IF(G28>0,'5. 공사내역서(입력)'!F16," ") | G28: ='5. 공사내역서(입력)'!D16 -> 0 | H28: =IF(G28>0,"m","") | I28: ='5. 공사내역서(입력)'!H16 -> 51000 | K28: =G28*I28 -> 0
E29: =IF(G29>0,'5. 공사내역서(입력)'!F17," ") | G29: ='5. 공사내역서(입력)'!D17 -> 0 | H29: =IF(G29>0,"m","") | I29: ='5. 공사내역서(입력)'!H17 -> 70800 | K29: =G29*I29 -> 0
E30: =IF(G30>0,'5. 공사내역서(입력)'!F18," ") | G30: ='5. 공사내역서(입력)'!D18 -> 0 | H30: =IF(G30>0,"m","") | I30: ='5. 공사내역서(입력)'!H18 -> 88200 | K30: =G30*I30 -> 0
E31: =IF(G31>0,'5. 공사내역서(입력)'!F19," ") | G31: ='5. 공사내역서(입력)'!D19 -> 0 | H31: =IF(G31>0,"m","") | I31: ='5. 공사내역서(입력)'!H19 -> 109700 | K31: =G31*I31 -> 0
A32: ='5. 공사내역서(입력)'!C20 -> 추가 강제전선관 배관 공사 | E32: =IF(G32>0,'5. 공사내역서(입력)'!F20," ") | G32: ='5. 공사내역서(입력)'!D20 -> 0 | H32: =IF(G32>0,"m","") | I32: ='5. 공사내역서(입력)'!H20 -> 3250 | K32: =G32*I32 -> 0
E33: =IF(G33>0,'5. 공사내역서(입력)'!F21," ") | G33: ='5. 공사내역서(입력)'!D21 -> 0 | H33: =IF(G33>0,"m","") | I33: ='5. 공사내역서(입력)'!H21 -> 4300 | K33: =G33*I33 -> 0
E34: =IF(G34>0,'5. 공사내역서(입력)'!F22," ") | G34: ='5. 공사내역서(입력)'!D22 -> 0 | H34: =IF(G34>0,"m","") | I34: ='5. 공사내역서(입력)'!H22 -> 5700 | K34: =G34*I34 -> 0
E35: =IF(G35>0,'5. 공사내역서(입력)'!F23," ") | G35: ='5. 공사내역서(입력)'!D23 -> 0 | H35: =IF(G35>0,"m","") | I35: ='5. 공사내역서(입력)'!H23 -> 7350 | K35: =G35*I35 -> 0
E36: =IF(G36>0,'5. 공사내역서(입력)'!F24," ") | G36: ='5. 공사내역서(입력)'!D24 -> 0 | H36: =IF(G36>0,"m","") | I36: ='5. 공사내역서(입력)'!H24 -> 8400 | K36: =G36*I36 -> 0
E37: =IF(G37>0,'5. 공사내역서(입력)'!F25," ") | G37: ='5. 공사내역서(입력)'!D25 -> 0 | H37: =IF(G37>0,"m","") | I37: ='5. 공사내역서(입력)'!H25 -> 11900 | K37: =G37*I37 -> 0
E38: =IF(G38>0,'5. 공사내역서(입력)'!F26," ") | G38: ='5. 공사내역서(입력)'!D26 -> 0 | H38: =IF(G38>0,"m","") | I38: ='5. 공사내역서(입력)'!H26 -> 15100 | K38: =G38*I38 -> 0
E39: =IF(G39>0,'5. 공사내역서(입력)'!F27," ") | G39: ='5. 공사내역서(입력)'!D27 -> 0 | H39: =IF(G39>0,"m","") | I39: ='5. 공사내역서(입력)'!H27 -> 17400 | K39: =G39*I39 -> 0
E40: =IF(G40>0,'5. 공사내역서(입력)'!F28," ") | G40: ='5. 공사내역서(입력)'!D28 -> 0 | H40: =IF(G40>0,"m","") | I40: ='5. 공사내역서(입력)'!H28 -> 28200 | K40: =G40*I40 -> 0
A41: ='5. 공사내역서(입력)'!C29 -> 기타비용 | E41: ='5. 공사내역서(입력)'!F29 -> 인건비 | G41: ='5. 공사내역서(입력)'!D29 -> 0 | H41: ='5. 공사내역서(입력)'!E29 -> 0 | I41: ='5. 공사내역서(입력)'!H29 -> 250000 | K41: =G41*I41 -> 0
E42: ='5. 공사내역서(입력)'!F30 -> 0 | G42: ='5. 공사내역서(입력)'!D30 -> 0 | H42: ='5. 공사내역서(입력)'!E30 -> 0 | I42: ='5. 공사내역서(입력)'!H30 -> 0 | K42: =G42*I42 -> 0
E43: ='5. 공사내역서(입력)'!F31 -> 0 | G43: ='5. 공사내역서(입력)'!D31 -> 0 | H43: ='5. 공사내역서(입력)'!E31 -> 0 | I43: ='5. 공사내역서(입력)'!H31 -> 0 | K43: =G43*I43 -> 0
E44: ='5. 공사내역서(입력)'!F32 -> 0 | G44: ='5. 공사내역서(입력)'!D32 -> 0 | H44: ='5. 공사내역서(입력)'!E32 -> 0 | I44: ='5. 공사내역서(입력)'!H32 -> 0 | K44: =G44*I44 -> 0
...

Sheet 표지-끝

Sheet 일위대가
B1: 일 위 대 가 표
B2: ─────────
B3: (표 2 - 1)
B4: 용역명 : 2022년 민간보급 완속충전기 설치공사 검토 | N4: 단위 : 원
A5: 번호 | B5: 명 칭 | C5: 규 격 | D5: 단위 | E5: 수량 | F5: 재료비 | H5: 노무비 | J5: 경비 | M5: 계 | N5: 비고
F6: 단가 | G6: 금액 | H6: 단가 | I6: 금액 | J6: 단가 | K6: 금액 | L6: 단가
A7: =+TRIM(CONCATENATE(B7,C7,D7)) -> [제 1-1호] 강제전선관(노출) 아연도 16 mm [M] | B7: [제 1-1호] 강제전선관(노출) 아연도 16 mm [M] | G7: =IF(E7*F7<>0, TRUNC(E7*F7, 1), "") | I7: =IF(E7*H7<>0,TRUNC(E7*H7, 1),"") | K7: =IF(E7*J7<>0,TRUNC(E7*J7, 1),"") | L7: =IF((F7+H7+J7)=0, "", (F7+H7+J7)) | M7: =IF(SUM(G7,I7,K7)<>0,TRUNC(SUM(G7,I7,K7),1),"")
A8: =+TRIM(CONCATENATE(B8,C8,D8)) -> 강제전선관(노출)아연도 16 mmM | B8: 강제전선관(노출) | C8: 아연도 16 mm | D8: M | E8: 1 | F8: =+VLOOKUP(A8,단가표!$A:$Q,17,FALSE) -> 2150 | G8: =INT(E8*F8) -> 2150 | I8: =INT(E8*H8) -> 0 | K8: =IF(E8*J8<>0,TRUNC(E8*J8, 1),"") | L8: =IF((F8+H8+J8)=0, "", (F8+H8+J8)) -> 2150 | M8: =SUM(G8,I8,K8) -> 2150
A9: =+TRIM(CONCATENATE(B9,C9,D9)) -> 노 무 비내선전공인 | B9: 노 무 비 | C9: 내선전공 | D9: 인 | E9: =+일위수량!E9 -> 0.096 | G9: =INT(E9*F9) -> 0 | H9: =+VLOOKUP(C9,단가표!$A:$Q,17,FALSE) -> 220079 | I9: =INT(E9*H9) -> 21127 | K9: =IF(E9*J9<>0,TRUNC(E9*J9, 1),"") | L9: =IF((F9+H9+J9)=0, "", (F9+H9+J9)) -> 220079 | M9: =SUM(G9,I9,K9) -> 21127
A10: =+TRIM(CONCATENATE(B10,C10,D10)) -> ( 합 계 ) | B10: ( 합 계 ) | G10: =SUM(G8:G9) -> 2150 | I10: =SUM(I8:I9) -> 21127 | K10: =SUM(K8:K9) -> 0 | L10: =IF((F10+H10+J10)=0, "", (F10+H10+J10)) | M10: =SUM(M8:M9) -> 23277
A11: =+TRIM(CONCATENATE(B11,C11,D11)) | G11: =INT(E11*F11) -> 0 | I11: =INT(E11*H11) -> 0 | K11: =IF(E11*J11<>0,TRUNC(E11*J11, 1),"") | L11: =IF((F11+H11+J11)=0, "", (F11+H11+J11)) | M11: =SUM(G11,I11,K11) -> 0
A12: =+TRIM(CONCATENATE(B12,C12,D12)) -> [제 1-2호] 강제전선관(노출) 아연도 22 mm [M] | B12: [제 1-2호] 강제전선관(노출) 아연도 22 mm [M] | G12: =IF(E12*F12<>0, TRUNC(E12*F12, 1), "") | I12: =IF(E12*H12<>0,TRUNC(E12*H12, 1),"") | K12: =IF(E12*J12<>0,TRUNC(E12*J12, 1),"") | L12: =IF((F12+H12+J12)=0, "", (F12+H12+J12)) | M12: =IF(SUM(G12,I12,K12)<>0,TRUNC(SUM(G12,I12,K12),1),"")
A13: =+TRIM(CONCATENATE(B13,C13,D13)) -> 강제전선관(노출)아연도 22 mmM | B13: 강제전선관(노출) | C13: 아연도 22 mm | D13: M | E13: 1 | F13: =+VLOOKUP(A13,단가표!$A:$Q,17,FALSE) -> 2780 | G13: =INT(E13*F13) -> 2780 | I13: =INT(E13*H13) -> 0 | K13: =IF(E13*J13<>0,TRUNC(E13*J13, 1),"") | L13: =IF((F13+H13+J13)=0, "", (F13+H13+J13)) -> 2780 | M13: =SUM(G13,I13,K13) -> 2780
A14: =+TRIM(CONCATENATE(B14,C14,D14)) -> 노 무 비내선전공인 | B14: 노 무 비 | C14: 내선전공 | D14: 인 | E14: =일위수량!E12 -> 0.132 | G14: =INT(E14*F14) -> 0 | H14: =+VLOOKUP(C14,단가표!$A:$Q,17,FALSE) -> 220079 | I14: =INT(E14*H14) -> 29050 | K14: =IF(E14*J14<>0,TRUNC(E14*J14, 1),"") | L14: =IF((F14+H14+J14)=0, "", (F14+H14+J14)) -> 220079 | M14: =SUM(G14,I14,K14) -> 29050
A15: =+TRIM(CONCATENATE(B15,C15,D15)) -> ( 합 계 ) | B15: ( 합 계 ) | G15: =SUM(G13:G14) -> 2780 | I15: =SUM(I13:I14) -> 29050 | K15: =SUM(K13:K14) -> 0 | L15: =IF((F15+H15+J15)=0, "", (F15+H15+J15)) | M15: =SUM(M13:M14) -> 31830
A16: =+TRIM(CONCATENATE(B16,C16,D16)) | G16: =INT(E16*F16) -> 0 | I16: =INT(E16*H16) -> 0 | K16: =IF(E16*J16<>0,TRUNC(E16*J16, 1),"") | L16: =IF((F16+H16+J16)=0, "", (F16+H16+J16)) | M16: =SUM(G16,I16,K16) -> 0
A17: =+TRIM(CONCATENATE(B17,C17,D17)) -> [제 1-3호] 강제전선관(노출) 아연도 28 mm [M] | B17: [제 1-3호] 강제전선관(노출) 아연도 28 mm [M] | G17: =INT(E17*F17) -> 0 | I17: =INT(E17*H17) -> 0 | K17: =IF(E17*J17<>0,TRUNC(E17*J17, 1),"") | L17: =IF((F17+H17+J17)=0, "", (F17+H17+J17)) | M17: =SUM(G17,I17,K17) -> 0
A18: =+TRIM(CONCATENATE(B18,C18,D18)) -> 강제전선관(노출)아연도 28 mmM | B18: 강제전선관(노출) | C18: 아연도 28 mm | D18: M | E18: 1 | F18: =+VLOOKUP(A18,단가표!$A:$Q,17,FALSE) -> 3620 | G18: =INT(E18*F18) -> 3620 | I18: =INT(E18*H18) -> 0 | K18: =IF(E18*J18<>0,TRUNC(E18*J18, 1),"") | L18: =IF((F18+H18+J18)=0, "", (F18+H18+J18)) -> 3620 | M18: =SUM(G18,I18,K18) -> 3620
A19: =+TRIM(CONCATENATE(B19,C19,D19)) -> 노 무 비내선전공인 | B19: 노 무 비 | C19: 내선전공 | D19: 인 | E19: =일위수량!E15 -> 0.168 | G19: =INT(E19*F19) -> 0 | H19: =+VLOOKUP(C19,단가표!$A:$Q,17,FALSE) -> 220079 | I19: =INT(E19*H19) -> 36973 | K19: =IF(E19*J19<>0,TRUNC(E19*J19, 1),"") | L19: =IF((F19+H19+J19)=0, "", (F19+H19+J19)) -> 220079 | M19: =SUM(G19,I19,K19) -> 36973
A20: =+TRIM(CONCATENATE(B20,C20,D20)) -> ( 합 계 ) | B20: ( 합 계 ) | G20: =SUM(G18:G19) -> 3620 | I20: =SUM(I18:I19) -> 36973 | K20: =SUM(K16:K19) -> 0 | L20: =IF((F20+H20+J20)=0, "", (F20+H20+J20)) | M20: =SUM(M18:M19) -> 40593
A21: =+TRIM(CONCATENATE(B21,C21,D21)) | G21: =INT(E21*F21) -> 0 | I21: =INT(E21*H21) -> 0 | K21: =IF(E21*J21<>0,TRUNC(E21*J21, 1),"") | L21: =IF((F21+H21+J21)=0, "", (F21+H21+J21)) | M21: =SUM(G21,I21,K21) -> 0
A22: =+TRIM(CONCATENATE(B22,C22,D22)) -> [제 1-4호] 강제전선관(노출) 아연도 36 mm [M] | B22: [제 1-4호] 강제전선관(노출) 아연도 36 mm [M] | G22: =INT(E22*F22) -> 0 | I22: =INT(E22*H22) -> 0 | K22: =IF(E22*J22<>0,TRUNC(E22*J22, 1),"") | L22: =IF((F22+H22+J22)=0, "", (F22+H22+J22)) | M22: =SUM(G22,I22,K22) -> 0
A23: =+TRIM(CONCATENATE(B23,C23,D23)) -> 강제전선관(노출)아연도 36 mmM | B23: 강제전선관(노출) | C23: 아연도 36 mm | D23: M | E23: 1 | F23: =+VLOOKUP(A23,단가표!$A:$Q,17,FALSE) -> 4650 | G23: =INT(E23*F23) -> 4650 | I23: =INT(E23*H23) -> 0 | K23: =IF(E23*J23<>0,TRUNC(E23*J23, 1),"") | L23: =IF((F23+H23+J23)=0, "", (F23+H23+J23)) -> 4650 | M23: =SUM(G23,I23,K23) -> 4650
A24: =+TRIM(CONCATENATE(B24,C24,D24)) -> 노 무 비내선전공인 | B24: 노 무 비 | C24: 내선전공 | D24: 인 | E24: =일위수량!E18 -> 0.24 | G24: =INT(E24*F24) -> 0 | H24: =+VLOOKUP(C24,단가표!$A:$Q,17,FALSE) -> 220079 | I24: =INT(E24*H24) -> 52818 | K24: =IF(E24*J24<>0,TRUNC(E24*J24, 1),"") | L24: =IF((F24+H24+J24)=0, "", (F24+H24+J24)) -> 220079 | M24: =SUM(G24,I24,K24) -> 52818
A25: =+TRIM(CONCATENATE(B25,C25,D25)) -> ( 합 계 ) | B25: ( 합 계 ) | G25: =SUM(G23:G24) -> 4650 | I25: =SUM(I23:I24) -> 52818 | K25: =SUM(K21:K24) -> 0 | L25: =IF((F25+H25+J25)=0, "", (F25+H25+J25)) | M25: =SUM(M23:M24) -> 57468
A26: =+TRIM(CONCATENATE(B26,C26,D26)) | G26: =INT(E26*F26) -> 0 | I26: =INT(E26*H26) -> 0 | K26: =IF(E26*J26<>0,TRUNC(E26*J26, 1),"") | L26: =IF((F26+H26+J26)=0, "", (F26+H26+J26)) | M26: =SUM(G26,I26,K26) -> 0
A27: =+TRIM(CONCATENATE(B27,C27,D27)) -> [제 1-5호] 강제전선관(노출) 아연도 42 mm [M] | B27: [제 1-5호] 강제전선관(노출) 아연도 42 mm [M] | G27: =INT(E27*F27) -> 0 | I27: =INT(E27*H27) -> 0 | K27: =IF(E27*J27<>0,TRUNC(E27*J27, 1),"") | L27: =IF((F27+H27+J27)=0, "", (F27+H27+J27)) | M27: =SUM(G27,I27,K27) -> 0
A28: =+TRIM(CONCATENATE(B28,C28,D28)) -> 강제전선관(노출)아연도 42 mmM | B28: 강제전선관(노출) | C28: 아연도 42 mm | D28: M | E28: 1 | F28: =+VLOOKUP(A28,단가표!$A:$Q,17,FALSE) -> 5320 | G28: =INT(E28*F28) -> 5320 | I28: =INT(E28*H28) -> 0 | K28: =IF(E28*J28<>0,TRUNC(E28*J28, 1),"") | L28: =IF((F28+H28+J28)=0, "", (F28+H28+J28)) -> 5320 | M28: =SUM(G28,I28,K28) -> 5320
A29: =+TRIM(CONCATENATE(B29,C29,D29)) -> 노 무 비내선전공인 | B29: 노 무 비 | C29: 내선전공 | D29: 인 | E29: =일위수량!E21 -> 0.3 | G29: =INT(E29*F29) -> 0 | H29: =+VLOOKUP(C29,단가표!$A:$Q,17,FALSE) -> 220079 | I29: =INT(E29*H29) -> 66023 | K29: =IF(E29*J29<>0,TRUNC(E29*J29, 1),"") | L29: =IF((F29+H29+J29)=0, "", (F29+H29+J29)) -> 220079 | M29: =SUM(G29,I29,K29) -> 66023
A30: =+TRIM(CONCATENATE(B30,C30,D30)) -> ( 합 계 ) | B30: ( 합 계 ) | G30: =SUM(G28:G29) -> 5320 | I30: =SUM(I28:I29) -> 66023 | K30: =SUM(K26:K29) -> 0 | L30: =IF((F30+H30+J30)=0, "", (F30+H30+J30)) | M30: =SUM(M28:M29) -> 71343
A31: =+TRIM(CONCATENATE(B31,C31,D31)) -> [제 1-6호] 강제전선관(노출) 아연도 54 mm [M] | B31: [제 1-6호] 강제전선관(노출) 아연도 54 mm [M] | G31: =INT(E31*F31) -> 0 | I31: =INT(E31*H31) -> 0 | K31: =IF(E31*J31<>0,TRUNC(E31*J31, 1),"") | L31: =IF((F31+H31+J31)=0, "", (F31+H31+J31)) | M31: =SUM(G31,I31,K31) -> 0
A32: =+TRIM(CONCATENATE(B32,C32,D32)) -> 강제전선관(노출)아연도 54 mmM | B32: 강제전선관(노출) | C32: 아연도 54 mm | D32: M | E32: 1 | F32: =+VLOOKUP(A32,단가표!$A:$Q,17,FALSE) -> 7510 | G32: =INT(E32*F32) -> 7510 | I32: =INT(E32*H32) -> 0 | K32: =IF(E32*J32<>0,TRUNC(E32*J32, 1),"") | L32: =IF((F32+H32+J32)=0, "", (F32+H32+J32)) -> 7510 | M32: =SUM(G32,I32,K32) -> 7510
A33: =+TRIM(CONCATENATE(B33,C33,D33)) -> 노 무 비내선전공인 | B33: 노 무 비 | C33: 내선전공 | D33: 인 | E33: =일위수량!E24 -> 0.408 | G33: =INT(E33*F33) -> 0 | H33: =+VLOOKUP(C33,단가표!$A:$Q,17,FALSE) -> 220079 | I33: =INT(E33*H33) -> 89792 | K33: =IF(E33*J33<>0,TRUNC(E33*J33, 1),"") | L33: =IF((F33+H33+J33)=0, "", (F33+H33+J33)) -> 220079 | M33: =SUM(G33,I33,K33) -> 89792
A34: =+TRIM(CONCATENATE(B34,C34,D34)) -> ( 합 계 ) | B34: ( 합 계 ) | G34: =SUM(G32:G33) -> 7510 | I34: =SUM(I32:I33) -> 89792 | K34: =SUM(K31:K33) -> 0 | L34: =IF((F34+H34+J34)=0, "", (F34+H34+J34)) | M34: =SUM(M32:M33) -> 97302
A35: =+TRIM(CONCATENATE(B35,C35,D35)) | G35: =INT(E35*F35) -> 0 | I35: =INT(E35*H35) -> 0 | K35: =IF(E35*J35<>0,TRUNC(E35*J35, 1),"") | L35: =IF((F35+H35+J35)=0, "", (F35+H35+J35)) | M35: =SUM(G35,I35,K35) -> 0
A36: =+TRIM(CONCATENATE(B36,C36,D36)) -> [제 1-7호] 강제전선관(노출) 아연도 70 mm [M] | B36: [제 1-7호] 강제전선관(노출) 아연도 70 mm [M] | G36: =INT(E36*F36) -> 0 | I36: =INT(E36*H36) -> 0 | K36: =IF(E36*J36<>0,TRUNC(E36*J36, 1),"") | L36: =IF((F36+H36+J36)=0, "", (F36+H36+J36)) | M36: =SUM(G36,I36,K36) -> 0
A37: =+TRIM(CONCATENATE(B37,C37,D37)) -> 강제전선관(노출)아연도 70 mmM | B37: 강제전선관(노출) | C37: 아연도 70 mm | D37: M | E37: 1 | F37: =+VLOOKUP(A37,단가표!$A:$Q,17,FALSE) -> 9570 | G37: =INT(E37*F37) -> 9570 | I37: =INT(E37*H37) -> 0 | K37: =IF(E37*J37<>0,TRUNC(E37*J37, 1),"") | L37: =IF((F37+H37+J37)=0, "", (F37+H37+J37)) -> 9570 | M37: =SUM(G37,I37,K37) -> 9570
A38: =+TRIM(CONCATENATE(B38,C38,D38)) -> 노 무 비내선전공인 | B38: 노 무 비 | C38: 내선전공 | D38: 인 | E38: =+일위수량!E27 -> 0.528 | G38: =INT(E38*F38) -> 0 | H38: =+VLOOKUP(C38,단가표!$A:$Q,17,FALSE) -> 220079 | I38: =INT(E38*H38) -> 116201 | K38: =IF(E38*J38<>0,TRUNC(E38*J38, 1),"") | L38: =IF((F38+H38+J38)=0, "", (F38+H38+J38)) -> 220079 | M38: =SUM(G38,I38,K38) -> 116201
A39: =+TRIM(CONCATENATE(B39,C39,D39)) -> ( 합 계 ) | B39: ( 합 계 ) | G39: =SUM(G37:G38) -> 9570 | I39: =SUM(I37:I38) -> 116201 | K39: =SUM(K35:K38) -> 0 | L39: =IF((F39+H39+J39)=0, "", (F39+H39+J39)) | M39: =SUM(M37:M38) -> 125771
A40: =+TRIM(CONCATENATE(B40,C40,D40)) | G40: =INT(E40*F40) -> 0 | I40: =INT(E40*H40) -> 0 | K40: =IF(E40*J40<>0,TRUNC(E40*J40, 1),"") | L40: =IF((F40+H40+J40)=0, "", (F40+H40+J40)) | M40: =SUM(G40,I40,K40) -> 0
...

Sheet 일위수량
B1: 일위대가 수량 산출표 | V1: 내선전공 | W1: 저압케이블전공 | X1: 배전전공 | Y1: 보통인부 | Z1: 특별인부 | AA1: 석공 | AB1: 콘크리트공
B2: ────────────
B3: (표 2 - 2)
B4: 용역명 : 2022년 민간보급 완속충전기 설치공사 검토 | O4: 단위 : 원
A5: 번호 | B5: 명 칭 | C5: 규 격 | D5: 단위 | E5: 수량 | I5: 코드 | J5: 공량산출 | N5: 품셈근거 | O5: 비고
E6: 결정수량 | F6: 할증 | G6: 산출수량 | H6: 재할% | J6: 명칭 | K6: 품셈 | L6: 할증% | M6: 공량
A7: =+B7&C7&D7 -> [ 제 1-1호 ] 강제전선관(노출) 아연도 16 mm [M] | B7: [ 제 1-1호 ] 강제전선관(노출) 아연도 16 mm [M]
A8: =+B8&C8&D8 -> 강제전선관(노출)아연도 16 mmM | B8: 강제전선관(노출) | C8: 아연도 16 mm | D8: M | E8: 1 | F8: =IF(G8<>0, E8-G8, "") -> 0 | G8: 1 | H8: 10 | I8: 56900017016 | J8: 내선전공 | K8: 0.08 | L8: 120 | M8: =IF(G8*K8=0, "", G8*K8*(L8/100)) -> 0.096 | N8: 전기5-1 | V8: =M8 -> 0.096
A9: =+B9&C9&D9 -> 노 무 비내선전공인 | B9: 노 무 비 | C9: 내선전공 | D9: 인 | E9: =+F9%*G9 -> 0.096 | F9: 100 | G9: =SUM(V8) -> 0.096 | M9: =IF(G9*K9=0, "", G9*K9*(L9/100)) | U9: 노임계 | V9: =SUM(V8) -> 0.096
A10: =+B10&C10&D10 -> [ 제 1-2호 ] 강제전선관(노출) 아연도 22 mm [M] | B10: [ 제 1-2호 ] 강제전선관(노출) 아연도 22 mm [M]
A11: =+B11&C11&D11 -> 강제전선관(노출)아연도 22 mmM | B11: 강제전선관(노출) | C11: 아연도 22 mm | D11: M | E11: 1 | F11: =IF(G11<>0, E11-G11, "") -> 0 | G11: 1 | H11: 10 | I11: 56900017016 | J11: 내선전공 | K11: 0.11 | L11: 120 | M11: =IF(G11*K11=0, "", G11*K11*(L11/100)) -> 0.132 | N11: 전기5-1 | V11: =M11 -> 0.132
A12: =+B12&C12&D12 -> 노 무 비내선전공인 | B12: 노 무 비 | C12: 내선전공 | D12: 인 | E12: =+F12%*G12 -> 0.132 | F12: 100 | G12: =SUM(V11) -> 0.132 | M12: =IF(G12*K12=0, "", G12*K12*(L12/100)) | U12: 노임계 | V12: =SUM(V11) -> 0.132
A13: =+B13&C13&D13 -> [ 제 1-3호 ] 강제전선관(노출) 아연도 28 mm [M] | B13: [ 제 1-3호 ] 강제전선관(노출) 아연도 28 mm [M]
A14: =+B14&C14&D14 -> 강제전선관(노출)아연도 28 mmM | B14: 강제전선관(노출) | C14: 아연도 28 mm | D14: M | E14: 1 | F14: =IF(G14<>0, E14-G14, "") -> 0 | G14: 1 | H14: 10 | I14: 56900017016 | J14: 내선전공 | K14: 0.14 | L14: 120 | M14: =IF(G14*K14=0, "", G14*K14*(L14/100)) -> 0.168 | N14: 전기5-1 | V14: =M14 -> 0.168
A15: =+B15&C15&D15 -> 노 무 비내선전공인 | B15: 노 무 비 | C15: 내선전공 | D15: 인 | E15: =+F15%*G15 -> 0.168 | F15: 100 | G15: =SUM(V14) -> 0.168 | M15: =IF(G15*K15=0, "", G15*K15*(L15/100)) | U15: 노임계 | V15: =SUM(V14) -> 0.168
A16: =+B16&C16&D16 -> [ 제 1-4호 ] 강제전선관(노출) 아연도 36 mm [M] | B16: [ 제 1-4호 ] 강제전선관(노출) 아연도 36 mm [M]
A17: =+B17&C17&D17 -> 강제전선관(노출)아연도 36 mmM | B17: 강제전선관(노출) | C17: 아연도 36 mm | D17: M | E17: 1 | F17: =IF(G17<>0, E17-G17, "") -> 0 | G17: 1 | H17: 10 | I17: 56900017016 | J17: 내선전공 | K17: 0.2 | L17: 120 | M17: =IF(G17*K17=0, "", G17*K17*(L17/100)) -> 0.24 | N17: 전기5-1 | V17: =M17 -> 0.24
A18: =+B18&C18&D18 -> 노 무 비내선전공인 | B18: 노 무 비 | C18: 내선전공 | D18: 인 | E18: =+F18%*G18 -> 0.24 | F18: 100 | G18: =SUM(V17) -> 0.24 | M18: =IF(G18*K18=0, "", G18*K18*(L18/100)) | U18: 노임계 | V18: =SUM(V17) -> 0.24
A19: =+B19&C19&D19 -> [ 제 1-5호 ] 강제전선관(노출) 아연도 42 mm [M] | B19: [ 제 1-5호 ] 강제전선관(노출) 아연도 42 mm [M]
A20: =+B20&C20&D20 -> 강제전선관(노출)아연도 42 mmM | B20: 강제전선관(노출) | C20: 아연도 42 mm | D20: M | E20: 1 | F20: =IF(G20<>0, E20-G20, "") -> 0 | G20: 1 | H20: 10 | I20: 56900017016 | J20: 내선전공 | K20: 0.25 | L20: 120 | M20: =IF(G20*K20=0, "", G20*K20*(L20/100)) -> 0.3 | N20: 전기5-1 | V20: =M20 -> 0.3
A21: =+B21&C21&D21 -> 노 무 비내선전공인 | B21: 노 무 비 | C21: 내선전공 | D21: 인 | E21: =+F21%*G21 -> 0.3 | F21: 100 | G21: =SUM(V20) -> 0.3 | M21: =IF(G21*K21=0, "", G21*K21*(L21/100)) | U21: 노임계 | V21: =SUM(V20) -> 0.3
A22: =+B22&C22&D22 -> [ 제 1-6호 ] 강제전선관(노출) 아연도 54 mm [M] | B22: [ 제 1-6호 ] 강제전선관(노출) 아연도 54 mm [M]
A23: =+B23&C23&D23 -> 강제전선관(노출)아연도 54 mmM | B23: 강제전선관(노출) | C23: 아연도 54 mm | D23: M | E23: 1 | F23: =IF(G23<>0, E23-G23, "") -> 0 | G23: 1 | H23: 10 | I23: 56900017016 | J23: 내선전공 | K23: 0.34 | L23: 120 | M23: =IF(G23*K23=0, "", G23*K23*(L23/100)) -> 0.408 | N23: 전기5-1 | V23: =M23 -> 0.408
A24: =+B24&C24&D24 -> 노 무 비내선전공인 | B24: 노 무 비 | C24: 내선전공 | D24: 인 | E24: =+F24%*G24 -> 0.408 | F24: 100 | G24: =SUM(V23) -> 0.408 | M24: =IF(G24*K24=0, "", G24*K24*(L24/100)) | U24: 노임계 | V24: =SUM(V23) -> 0.408
A25: =+B25&C25&D25 -> [ 제 1-7호 ] 강제전선관(노출) 아연도 70 mm [M] | B25: [ 제 1-7호 ] 강제전선관(노출) 아연도 70 mm [M]
A26: =+B26&C26&D26 -> 강제전선관(노출)아연도 70 mmM | B26: 강제전선관(노출) | C26: 아연도 70 mm | D26: M | E26: 1 | F26: =IF(G26<>0, E26-G26, "") -> 0 | G26: 1 | H26: 10 | I26: 56900017016 | J26: 내선전공 | K26: 0.44 | L26: 120 | M26: =IF(G26*K26=0, "", G26*K26*(L26/100)) -> 0.528 | N26: 전기5-1 | V26: =M26 -> 0.528
A27: =+B27&C27&D27 -> 노 무 비내선전공인 | B27: 노 무 비 | C27: 내선전공 | D27: 인 | E27: =+F27%*G27 -> 0.528 | F27: 100 | G27: =SUM(V26) -> 0.528 | M27: =IF(G27*K27=0, "", G27*K27*(L27/100)) | U27: 노임계 | V27: =SUM(V26) -> 0.528
A28: =+B28&C28&D28 -> [ 제 1-8호 ] 강제전선관(노출) 아연도 82 mm [M] | B28: [ 제 1-8호 ] 강제전선관(노출) 아연도 82 mm [M]
A29: =+B29&C29&D29 -> 강제전선관(노출)아연도 82 mmM | B29: 강제전선관(노출) | C29: 아연도 82 mm | D29: M | E29: 1 | F29: =IF(G29<>0, E29-G29, "") -> 0 | G29: 1 | H29: 10 | I29: 56900017016 | J29: 내선전공 | K29: 0.54 | L29: 120 | M29: =IF(G29*K29=0, "", G29*K29*(L29/100)) -> 0.648 | N29: 전기5-1 | V29: =M29 -> 0.648
A30: =+B30&C30&D30 -> 노 무 비내선전공인 | B30: 노 무 비 | C30: 내선전공 | D30: 인 | E30: =+F30%*G30 -> 0.648 | F30: 100 | G30: =SUM(V29) -> 0.648 | M30: =IF(G30*K30=0, "", G30*K30*(L30/100)) | U30: 노임계 | V30: =SUM(V29) -> 0.648
A31: =+B31&C31&D31 -> [ 제 1-9호 ] 강제전선관(노출) 아연도 104 mm [M] | B31: [ 제 1-9호 ] 강제전선관(노출) 아연도 104 mm [M]
A32: =+B32&C32&D32 -> 강제전선관(노출)아연도 104 mmM | B32: 강제전선관(노출) | C32: 아연도 104 mm | D32: M | E32: 1 | F32: =IF(G32<>0, E32-G32, "") -> 0 | G32: 1 | H32: 10 | I32: 56900017016 | J32: 내선전공 | K32: 0.71 | L32: 120 | M32: =IF(G32*K32=0, "", G32*K32*(L32/100)) -> 0.852 | N32: 전기5-1 | V32: =M32 -> 0.852
A33: =+B33&C33&D33 -> 노 무 비내선전공인 | B33: 노 무 비 | C33: 내선전공 | D33: 인 | E33: =+F33%*G33 -> 0.852 | F33: 100 | G33: =SUM(V32) -> 0.852 | M33: =IF(G33*K33=0, "", G33*K33*(L33/100)) | U33: 노임계 | V33: =SUM(V32) -> 0.852
A34: =+B34&C34&D34 -> [제 2-1호] 경질비닐전선관 HI 22 mm [M] | B34: [제 2-1호] 경질비닐전선관 HI 22 mm [M]
A35: =+B35&C35&D35 -> 경질비닐전선관HI 22 mmM | B35: 경질비닐전선관 | C35: HI 22 mm | D35: M | E35: 1 | F35: =IF(G35<>0, E35-G35, "") -> 0 | G35: 1 | H35: 10 | I35: 56900017016 | J35: 내선전공 | K35: 0.06 | L35: 100 | M35: =IF(G35*K35=0, "", G35*K35*(L35/100)) -> 0.06 | N35: 전기5-1 | V35: =M35 -> 0.06
A36: =+B36&C36&D36 -> 노 무 비내선전공인 | B36: 노 무 비 | C36: 내선전공 | D36: 인 | E36: =+F36%*G36 -> 0.06 | F36: 100 | G36: =SUM(V35) -> 0.06 | M36: =IF(G36*K36=0, "", G36*K36*(L36/100)) | U36: 노임계 | V36: =SUM(V35) -> 0.06
A37: =+B37&C37&D37 -> [제 2-2호] 경질비닐전선관 HI 28 mm [M] | B37: [제 2-2호] 경질비닐전선관 HI 28 mm [M]
A38: =+B38&C38&D38 -> 경질비닐전선관HI 28 mmM | B38: 경질비닐전선관 | C38: HI 28 mm | D38: M | E38: 1 | F38: =IF(G38<>0, E38-G38, "") -> 0 | G38: 1 | H38: 10 | I38: 56900017016 | J38: 내선전공 | K38: 0.08 | L38: 100 | M38: =IF(G38*K38=0, "", G38*K38*(L38/100)) -> 0.08 | N38: 전기5-1 | V38: =M38 -> 0.08
A39: =+B39&C39&D39 -> 노 무 비내선전공인 | B39: 노 무 비 | C39: 내선전공 | D39: 인 | E39: =+F39%*G39 -> 0.08 | F39: 100 | G39: =SUM(V38) -> 0.08 | M39: =IF(G39*K39=0, "", G39*K39*(L39/100)) | U39: 노임계 | V39: =SUM(V38) -> 0.08
A40: =+B40&C40&D40 -> [제 2-3호] 경질비닐전선관 HI 36 mm [M] | B40: [제 2-3호] 경질비닐전선관 HI 36 mm [M]
...

Sheet 단가표
B1: 단 가 조 사 표
B2: ──────────
B3: (표 3)
B4: 용역명 : 2022년 민간보급 완속충전기 설치공사 검토 | Q4: 단위 : 원
B5: 품 명 | C5: 규 격 | D5: 단위 | E5: 유통물가(7월호) | G5: 거래가격(7월호) | I5: 물가정보(7월호) | K5: 물가자료(7월호) | M5: 조달청 가격정보 | N5: 견 적 단 가 | P5: 최저단가 | Q5: 적용단가 | R5: 자재적용율 | S5: 8/30요청금액 | U5: 노무비적용율
E6: 단가 | F6: PAGE | G6: 단가 | H6: PAGE | I6: 단가 | J6: PAGE | K6: 단가 | L6: PAGE | N6: A업체 | O6: B업체 | R6: 0.85 | U6: 0.85
A7: =+CONCATENATE(B7,C7,D7) -> 강제전선관(노출)아연도 16 mmM | B7: 강제전선관(노출) | C7: 아연도 16 mm | D7: M | E7: 3375 | F7: 864 | G7: 2980 | H7: 1028 | I7: 3214 | J7: 1230 | K7: 3440 | L7: 1123 | M7: 2530 | P7: =+MIN(E7,G7,I7,K7,M7,N7,O7) -> 2530 | Q7: =+TRUNC(P7*$R$6,-1) -> 2150
A8: =+CONCATENATE(B8,C8,D8) -> 강제전선관(노출)아연도 22 mmM | B8: 강제전선관(노출) | C8: 아연도 22 mm | D8: M | E8: 4368 | F8: 864 | G8: 3854 | H8: 1028 | I8: 4160 | J8: 1230 | K8: 4450 | L8: 1123 | M8: 3274 | P8: =+MIN(E8,G8,I8,K8,M8,N8,O8) -> 3274 | Q8: =+TRUNC(P8*$R$6,-1) -> 2780
A9: =+CONCATENATE(B9,C9,D9) -> 강제전선관(노출)아연도 28 mmM | B9: 강제전선관(노출) | C9: 아연도 28 mm | D9: M | E9: 5710 | F9: 864 | G9: 5017 | H9: 1028 | I9: 5438 | J9: 1230 | K9: 5820 | L9: 1123 | M9: 4264 | P9: =+MIN(E9,G9,I9,K9,M9,N9,O9) -> 4264 | Q9: =+TRUNC(P9*$R$6,-1) -> 3620
A10: =+CONCATENATE(B10,C10,D10) -> 강제전선관(노출)아연도 36 mmM | B10: 강제전선관(노출) | C10: 아연도 36 mm | D10: M | E10: 7307 | F10: 864 | G10: 6417 | H10: 1028 | I10: 6959 | J10: 1230 | K10: 7440 | L10: 1123 | M10: 5475 | P10: =+MIN(E10,G10,I10,K10,M10,N10,O10) -> 5475 | Q10: =+TRUNC(P10*$R$6,-1) -> 4650
A11: =+CONCATENATE(B11,C11,D11) -> 강제전선관(노출)아연도 42 mmM | B11: 강제전선관(노출) | C11: 아연도 42 mm | D11: M | E11: 8402 | F11: 864 | G11: 7378 | H11: 1028 | I11: 8002 | J11: 1230 | K11: 8560 | L11: 1123 | M11: 6269 | P11: =+MIN(E11,G11,I11,K11,M11,N11,O11) -> 6269 | Q11: =+TRUNC(P11*$R$6,-1) -> 5320
A12: =+CONCATENATE(B12,C12,D12) -> 강제전선관(노출)아연도 54 mmM | B12: 강제전선관(노출) | C12: 아연도 54 mm | D12: M | E12: 11801 | F12: 864 | G12: 10363 | H12: 1028 | I12: 11239 | J12: 1230 | K12: 12020 | L12: 1123 | M12: 8844 | P12: =+MIN(E12,G12,I12,K12,M12,N12,O12) -> 8844 | Q12: =+TRUNC(P12*$R$6,-1) -> 7510
A13: =+CONCATENATE(B13,C13,D13) -> 강제전선관(노출)아연도 70 mmM | B13: 강제전선관(노출) | C13: 아연도 70 mm | D13: M | E13: 15043 | F13: 864 | G13: 13211 | H13: 1028 | I13: 14327 | J13: 1230 | K13: 15320 | L13: 1123 | M13: 11260 | P13: =+MIN(E13,G13,I13,K13,M13,N13,O13) -> 11260 | Q13: =+TRUNC(P13*$R$6,-1) -> 9570
A14: =+CONCATENATE(B14,C14,D14) -> 강제전선관(노출)아연도 82 mmM | B14: 강제전선관(노출) | C14: 아연도 82 mm | D14: M | E14: 17332 | F14: 864 | G14: 15192 | H14: 1028 | I14: 16507 | J14: 1230 | K14: 17660 | L14: 1123 | M14: 12972 | P14: =+MIN(E14,G14,I14,K14,M14,N14,O14) -> 12972 | Q14: =+TRUNC(P14*$R$6,-1) -> 11020
A15: =+CONCATENATE(B15,C15,D15) -> 강제전선관(노출)아연도 104 mmM | B15: 강제전선관(노출) | C15: 아연도 104 mm | D15: M | E15: 27983 | F15: 864 | G15: 24523 | H15: 1028 | I15: 26650 | J15: 1230 | K15: 28550 | L15: 1123 | M15: 20843 | P15: =+MIN(E15,G15,I15,K15,M15,N15,O15) -> 20843 | Q15: =+TRUNC(P15*$R$6,-1) -> 17710
A16: =+CONCATENATE(B16,C16,D16) -> 경질비닐전선관HI 22 mmM | B16: 경질비닐전선관 | C16: HI 22 mm | D16: M | E16: 480 | F16: 860 | G16: 400 | H16: 1023 | I16: 480 | J16: 1232 | K16: 470 | L16: 1129 | M16: 350 | P16: =+MIN(E16,G16,I16,K16,M16,N16,O16) -> 350 | Q16: =+TRUNC(P16*$R$6,-1) -> 290
A17: =+CONCATENATE(B17,C17,D17) -> 경질비닐전선관HI 28 mmM | B17: 경질비닐전선관 | C17: HI 28 mm | D17: M | E17: 929 | F17: 860 | G17: 774 | H17: 1023 | I17: 929 | J17: 1232 | K17: 890 | L17: 1129 | M17: 700 | P17: =+MIN(E17,G17,I17,K17,M17,N17,O17) -> 700 | Q17: =+TRUNC(P17*$R$6,-1) -> 590
A18: =+CONCATENATE(B18,C18,D18) -> 경질비닐전선관HI 36 mmM | B18: 경질비닐전선관 | C18: HI 36 mm | D18: M | E18: 1249 | F18: 860 | G18: 1121 | H18: 1023 | I18: 1249 | J18: 1232 | K18: 1440 | L18: 1129 | M18: 976 | P18: =+MIN(E18,G18,I18,K18,M18,N18,O18) -> 976 | Q18: =+TRUNC(P18*$R$6,-1) -> 820
... A27: =+CONCATENATE(B27,C27,D27) -> 파상형 폴리에틸렌 전선관100㎜M | B27: 파상형 폴리에틸렌 전선관 | C27: 100㎜ | D27: M | E27: 2013 | F27: 861 | G27: 2188 | H27: 1024 | I27: 2013 | J27: 1230 | K27: 1980 | L27: 1128 | M27: 1784 | P27: =+MIN(E27,G27,I27,K27,M27,N27,O27) -> 1784 | Q27: =+TRUNC(P27*$R$6,-1) -> 1510
A28: =+CONCATENATE(B28,C28,D28) -> 1종금속제가요전선관16 mm 일반-방수M | B28: 1종금속제가요전선관 | C28: 16 mm 일반-방수 | D28: M | E28: 700 | F28: 860 | I28: 594 | J28: 1231 | K28: 700 | L28: 1123 | M28: 733 | P28: =+MIN(E28,G28,I28,K28,M28,N28,O28) -> 594 | Q28: =+TRUNC(P28*$R$6,-1) -> 500
A29: =+CONCATENATE(B29,C29,D29) -> 1종금속제가요전선관22 mm 일반-방수M | B29: 1종금속제가요전선관 | C29: 22 mm 일반-방수 | D29: M | E29: 850 | F29: 860 | I29: 1128 | J29: 1231 | K29: 850 | L29: 1123 | M29: 937 | P29: =+MIN(E29,G29,I29,K29,M29,N29,O29) -> 850 | Q29: =+TRUNC(P29*$R$6,-1) -> 720
A30: =+CONCATENATE(B30,C30,D30) -> 1종금속제가요전선관28 mm 일반-방수M | B30: 1종금속제가요전선관 | C30: 28 mm 일반-방수 | D30: M | E30: 1100 | F30: 860 | I30: 1320 | J30: 1231 | K30: 1100 | L30: 1123 | M30: 1102 | P30: =+MIN(E30,G30,I30,K30,M30,N30,O30) -> 1100 | Q30: =+TRUNC(P30*$R$6,-1) -> 930
A31: =+CONCATENATE(B31,C31,D31) -> 1종금속제가요전선관36 mm 일반-방수M | B31: 1종금속제가요전선관 | C31: 36 mm 일반-방수 | D31: M | E31: 2200 | F31: 860 | I31: 1716 | J31: 1231 | K31: 2200 | L31: 1123 | M31: 1667 | P31: =+MIN(E31,G31,I31,K31,M31,N31,O31) -> 1667 | Q31: =+TRUNC(P31*$R$6,-1) -> 1410
A32: =+CONCATENATE(B32,C32,D32) -> 1종금속제가요전선관42 mm 일반-방수M | B32: 1종금속제가요전선관 | C32: 42 mm 일반-방수 | D32: M | E32: 2800 | F32: 860 | I32: 2760 | J32: 1231 | K32: 2800 | L32: 1123 | M32: 2205 | P32: =+MIN(E32,G32,I32,K32,M32,N32,O32) -> 2205 | Q32: =+TRUNC(P32*$R$6,-1) -> 1870
A33: =+CONCATENATE(B33,C33,D33) -> 1종금속제가요전선관54 mm 일반-방수M | B33: 1종금속제가요전선관 | C33: 54 mm 일반-방수 | D33: M | E33: 3800 | F33: 860 | I33: 3564 | J33: 1231 | K33: 3800 | L33: 1123 | M33: 3064 | P33: =+MIN(E33,G33,I33,K33,M33,N33,O33) -> 3064 | Q33: =+TRUNC(P33*$R$6,-1) -> 2600
A34: =+CONCATENATE(B34,C34,D34) -> 1종금속제가요전선관70 mm 일반-방수M | B34: 1종금속제가요전선관 | C34: 70 mm 일반-방수 | D34: M | E34: 4950 | F34: 860 | I34: 6468 | J34: 1231 | K34: 4950 | L34: 1123 | M34: 7190 | P34: =+MIN(E34,G34,I34,K34,M34,N34,O34) -> 4950 | Q34: =+TRUNC(P34*$R$6,-1) -> 4200
A35: =+CONCATENATE(B35,C35,D35) -> 1종금속제가요전선관82 mm 일반-방수M | B35: 1종금속제가요전선관 | C35: 82 mm 일반-방수 | D35: M | E35: 6000 | F35: 860 | I35: 8184 | J35: 1231 | K35: 6000 | L35: 1123 | M35: 12980 | P35: =+MIN(E35,G35,I35,K35,M35,N35,O35) -> 6000 | Q35: =+TRUNC(P35*$R$6,-1) -> 5100
A36: =+CONCATENATE(B36,C36,D36) -> 1종금속제가요전선관104 mm 일반-방수M | B36: 1종금속제가요전선관 | C36: 104 mm 일반-방수 | D36: M | E36: 9000 | F36: 860 | I36: 12840 | J36: 1231 | K36: 9000 | L36: 1123 | P36: =+MIN(E36,G36,I36,K36,M36,N36,O36) -> 9000 | Q36: =+TRUNC(P36*$R$6,-1) -> 7650
A37: =+CONCATENATE(B37,C37,D37) -> 풀박스150×150×100개 | B37: 풀박스 | C37: 150×150×100 | D37: 개 | E37: 3245 | F37: 873 | G37: 7510 | H37: 1027 | I37: 3245 | J37: 1235 | K37: 3520 | L37: 1127 | M37: 2757 | P37: =+MIN(E37,G37,I37,K37,M37,N37,O37) -> 2757 | Q37: =+TRUNC(P37*$R$6,-1) -> 2340
A38: =+CONCATENATE(B38,C38,D38) -> 풀박스200×200×150개 | B38: 풀박스 | C38: 200×200×150 | D38: 개 | E38: 5379 | F38: 873 | G38: 12500 | H38: 1027 | I38: 5379 | J38: 1235 | K38: 6000 | L38: 1127 | M38: 4571 | P38: =+MIN(E38,G38,I38,K38,M38,N38,O38) -> 4571 | Q38: =+TRUNC(P38*$R$6,-1) -> 3880
A39: =+CONCATENATE(B39,C39,D39) -> 풀박스300×300×200개 | B39: 풀박스 | C39: 300×300×200 | D39: 개 | E39: 11935 | F39: 873 | G39: 23400 | H39: 1027 | I39: 11935 | J39: 1235 | K39: 11520 | L39: 1127 | M39: 9688 | P39: =+MIN(E39,G39,I39,K39,M39,N39,O39) -> 9688 | Q39: =+TRUNC(P39*$R$6,-1) -> 8230
A40: =+CONCATENATE(B40,C40,D40) -> 풀박스500×500×200개 | B40: 풀박스 | C40: 500×500×200 | D40: 개 | E40: 35805 | F40: 873 | I40: 35805 | J40: 1235 | M40: 30433 | P40: =+MIN(E40,G40,I40,K40,M40,N40,O40) -> 30433 | Q40: =+TRUNC(P40*$R$6,-1) -> 25860
A41: =+CONCATENATE(B41,C41,D41) -> 풀박스800×800×200개 | B41: 풀박스 | C41: 800×800×200 | D41: 개 | N41: 40000 | O41: 40800 | P41: =+MIN(E41,G41,I41,K41,M41,N41,O41) -> 40000 | Q41: =+TRUNC(P41*$R$6,-1) -> 34000
A42: =+CONCATENATE(B42,C42,D42) -> 풀박스1000×500×200개 | B42: 풀박스 | C42: 1000×500×200 | D42: 개 | N42: 41000 | O42: 45000 | P42: =+MIN(E42,G42,I42,K42,M42,N42,O42) -> 41000 | Q42: =+TRUNC(P42*$R$6,-1) -> 34850
A43: =+CONCATENATE(B43,C43,D43) -> 풀박스1000×1000×200개 | B43: 풀박스 | C43: 1000×1000×200 | D43: 개 | N43: 48000 | O43: 51000 | P43: =+MIN(E43,G43,I43,K43,M43,N43,O43) -> 48000 | Q43: =+TRUNC(P43*$R$6,-1) -> 40800
A44: =+CONCATENATE(B44,C44,D44) -> 풀박스1600×1600×200개 | B44: 풀박스 | C44: 1600×1600×200 | D44: 개 | N44: 98000 | O44: 108000 | P44: =+MIN(E44,G44,I44,K44,M44,N44,O44) -> 98000 | Q44: =+TRUNC(P44*$R$6,-1) -> 83300
A45: =+CONCATENATE(B45,C45,D45) -> 풀박스SUS 400×400×200개 | B45: 풀박스 | C45: SUS 400×400×200 | D45: 개 | G45: 73700 | H45: 1027 | N45: 105270 | O45: 107400 | P45: =+MIN(E45,G45,I45,K45,M45,N45,O45) -> 73700 | Q45: =+TRUNC(P45*$R$6,-1) -> 62640
A46: =+CONCATENATE(B46,C46,D46) -> 풀박스SUS 500×500×200개 | B46: 풀박스 | C46: SUS 500×500×200 | D46: 개 | G46: 84300 | H46: 1027 | N46: 198000 | O46: 202000 | P46: =+MIN(E46,G46,I46,K46,M46,N46,O46) -> 84300 | Q46: =+TRUNC(P46*$R$6,-1) -> 71650
A47: =+CONCATENATE(B47,C47,D47) -> 풀박스SUS 600×600×200개 | B47: 풀박스 | C47: SUS 600×600×200 | D47: 개 | N47: 266101 | O47: 271400 | P47: =+MIN(E47,G47,I47,K47,M47,N47,O47) -> 266101 | Q47: =+TRUNC(P47*$R$6,-1) -> 226180
A48: =+CONCATENATE(B48,C48,D48) -> 풀박스SUS 800×400×400개 | B48: 풀박스 | C48: SUS 800×400×400 | D48: 개 | N48: 385000 | O48: 392700 | P48: =+MIN(E48,G48,I48,K48,M48,N48,O48) -> 385000 | Q48: =+TRUNC(P48*$R$6,-1) -> 327250
...
